# setTimeout でのエラー

<<<<<<< HEAD:1-js/11-async/04-promise-error-handling/01-error-async/task.md
`.catch` はトリガされると思いますか？またその理由を説明できますか？
=======
What do you think? Will the `.catch` trigger? Explain your answer.
>>>>>>> d694e895efe89922a109702085b6ca1efeffea10:1-js/11-async/04-promise-error-handling/01-error-async/task.md

```js
new Promise(function(resolve, reject) {
  setTimeout(() => {
    throw new Error("Whoops!");
  }, 1000);
}).catch(alert);
```
